Workbook
Name Slicer_Calendar__Month: #N/A
Name Slicer_registration_date__Year: #N/A

Sheet Billing Data
A1: bill_id | B1: patient_id | C1: treatment_id | D1: bill_date | E1: amount | F1: payment_method | G1: payment_status | H1: bill_date (Year) | I1: bill_date (Month Index) | J1: bill_date (Month)
A2: B005 | B2: P040 | C2: T005 | D2: 45113 | E2: 582.05 | F2: Credit Card | G2: Pending | H2: 2023 | I2: 7 | J2: Jul
A3: B009 | B3: P039 | C3: T009 | D3: 44990 | E3: 4541.14 | F3: Credit Card | G3: Paid | H3: 2023 | I3: 3 | J3: Mar
A4: B014 | B4: P012 | C4: T014 | D4: 45071 | E4: 2082.3 | F4: Credit Card | G4: Paid | H4: 2023 | I4: 5 | J4: May
A5: B017 | B5: P037 | C5: T017 | D5: 45118 | E5: 1655.49 | F5: Credit Card | G5: Pending | H5: 2023 | I5: 7 | J5: Jul
A6: B020 | B6: P014 | C6: T020 | D6: 45265 | E6: 4113.62 | F6: Credit Card | G6: Failed | H6: 2023 | I6: 12 | J6: Dec
A7: B022 | B7: P005 | C7: T022 | D7: 45244 | E7: 1900.88 | F7: Credit Card | G7: Failed | H7: 2023 | I7: 11 | J7: Nov
A8: B023 | B8: P047 | C8: T023 | D8: 45055 | E8: 3246.5 | F8: Credit Card | G8: Pending | H8: 2023 | I8: 5 | J8: May
A9: B028 | B9: P012 | C9: T028 | D9: 45228 | E9: 1315.17 | F9: Credit Card | G9: Paid | H9: 2023 | I9: 10 | J9: Oct
A10: B030 | B10: P026 | C10: T030 | D10: 45167 | E10: 1316.47 | F10: Credit Card | G10: Pending | H10: 2023 | I10: 8 | J10: Aug
A11: B031 | B11: P026 | C11: T031 | D11: 45020 | E11: 2863.24 | F11: Credit Card | G11: Pending | H11: 2023 | I11: 4 | J11: Apr
A12: B033 | B12: P021 | C12: T033 | D12: 45192 | E12: 980.95 | F12: Credit Card | G12: Paid | H12: 2023 | I12: 9 | J12: Sep
A13: B038 | B13: P037 | C13: T038 | D13: 44980 | E13: 4126.97 | F13: Credit Card | G13: Failed | H13: 2023 | I13: 2 | J13: Feb
... A201: B198 | B201: P022 | C201: T198 | D201: 45061 | E201: 3383.72 | F201: Cash | G201: Failed | H201: 2023 | I201: 5 | J201: May

Sheet Doctor Data
A1: doctor_id | B1: Doctor Name | C1: specialization | D1: phone_number | E1: years_experience | F1: hospital_branch | G1: email
A2: D001 | B2: David Taylor | C2: Dermatology | D2: 8322010158 | E2: 17 | F2: Westside Clinic | G2: dr.david.taylor@hospital.com
A3: D002 | B3: Jane Davis | C3: Pediatrics | D3: 9004382050 | E3: 24 | F3: Eastside Clinic | G3: dr.jane.davis@hospital.com
A4: D003 | B4: Jane Smith | C4: Pediatrics | D4: 8737740598 | E4: 19 | F4: Eastside Clinic | G4: dr.jane.smith@hospital.com
A5: D004 | B5: David Jones | C5: Pediatrics | D5: 6594221991 | E5: 28 | F5: Central Hospital | G5: dr.david.jones@hospital.com
A6: D005 | B6: Sarah Taylor | C6: Dermatology | D6: 9118538547 | E6: 26 | F6: Central Hospital | G6: dr.sarah.taylor@hospital.com
A7: D006 | B7: Alex Davis | C7: Pediatrics | D7: 6570137231 | E7: 23 | F7: Central Hospital | G7: dr.alex.davis@hospital.com
A8: D007 | B8: Robert Davis | C8: Oncology | D8: 8217493115 | E8: 26 | F8: Westside Clinic | G8: dr.robert.davis@hospital.com
A9: D008 | B9: Linda Brown | C9: Dermatology | D9: 9069162601 | E9: 5 | F9: Westside Clinic | G9: dr.linda.brown@hospital.com
A10: D009 | B10: Sarah Smith | C10: Pediatrics | D10: 7387087517 | E10: 26 | F10: Central Hospital | G10: dr.sarah.smith@hospital.com
A11: D010 | B11: Linda Wilson | C11: Oncology | D11: 6176383634 | E11: 21 | F11: Eastside Clinic | G11: dr.linda.wilson@hospital.com

Sheet Patient Data
A1: patient_id | B1: patient name | C1: gender | D1: date_of_birth | E1: contact_number | F1: address | G1: registration_date | H1: insurance_provider | I1: insurance_number | J1: email | K1: registration_date (Year) | L1: registration_date (Month Index) | M1: registration_date (Month) | N1: Age2 | O1: Age Group | P1: Patient Satisfaction
A2: P001 | B2: David Williams | C2: Female | D2: 20244 | E2: 6939585183 | F2: 789 Pine Rd | G2: 44735 | H2: WellnessCorp | I2: INS840674 | J2: david.williams@mail.com | K2: 2022 | L2: 6 | M2: Jun | N2: 37 | O2: =IF(N2<=20,"0-20",IF(N2<=40,"21-40",IF(N2<=60,"41-60",IF(N2<=80,"61-80","81+")))) -> 21-40 | P2: 8.6
A3: P002 | B3: Emily Smith | C3: Female | D3: 30967 | E3: 8228188767 | F3: 321 Maple Dr | G3: 44576 | H3: PulseSecure | I3: INS354079 | J3: emily.smith@mail.com | K3: 2022 | L3: 1 | M3: Jan | N3: 82 | O3: =IF(N3<=20,"0-20",IF(N3<=40,"21-40",IF(N3<=60,"41-60",IF(N3<=80,"61-80","81+")))) -> 81+ | P3: 8.5
A4: P003 | B4: Laura Jones | C4: Male | D4: 28358 | E4: 8397029847 | F4: 321 Maple Dr | G4: 44599 | H4: PulseSecure | I4: INS650929 | J4: laura.jones@mail.com | K4: 2022 | L4: 2 | M4: Feb | N4: 60 | O4: =IF(N4<=20,"0-20",IF(N4<=40,"21-40",IF(N4<=60,"41-60",IF(N4<=80,"61-80","81+")))) -> 41-60 | P4: 9.5
A5: P004 | B5: Michael Johnson | C5: Female | D5: 29637 | E5: 9019443432 | F5: 123 Elm St | G5: 44257 | H5: HealthIndia | I5: INS789944 | J5: michael.johnson@mail.com | K5: 2021 | L5: 3 | M5: Mar | N5: 43 | O5: =IF(N5<=20,"0-20",IF(N5<=40,"21-40",IF(N5<=60,"41-60",IF(N5<=80,"61-80","81+")))) -> 41-60 | P5: 9.9
A6: P005 | B6: David Wilson | C6: Male | D6: 22090 | E6: 7734463155 | F6: 123 Elm St | G6: 44468 | H6: MedCare Plus | I6: INS788105 | J6: david.wilson@mail.com | K6: 2021 | L6: 9 | M6: Sep | N6: 76 | O6: =IF(N6<=20,"0-20",IF(N6<=40,"21-40",IF(N6<=60,"41-60",IF(N6<=80,"61-80","81+")))) -> 61-80 | P6: 7.6
A7: P006 | B7: Linda Jones | C7: Male | D7: 23178 | E7: 7561777264 | F7: 321 Maple Dr | G7: 44836 | H7: HealthIndia | I7: INS613758 | J7: linda.jones@mail.com | K7: 2022 | L7: 10 | M7: Oct | N7: 27 | O7: =IF(N7<=20,"0-20",IF(N7<=40,"21-40",IF(N7<=60,"41-60",IF(N7<=80,"61-80","81+")))) -> 21-40 | P7: 7.4
A8: P007 | B8: Alex Johnson | C8: Female | D8: 32667 | E8: 6278710077 | F8: 789 Pine Rd | G8: 44555 | H8: MedCare Plus | I8: INS465890 | J8: alex.johnson@mail.com | K8: 2021 | L8: 12 | M8: Dec | N8: 29 | O8: =IF(N8<=20,"0-20",IF(N8<=40,"21-40",IF(N8<=60,"41-60",IF(N8<=80,"61-80","81+")))) -> 21-40 | P8: 9.8
A9: P008 | B9: David Davis | C9: Female | D9: 27946 | E9: 7090558393 | F9: 456 Oak Ave | G9: 44341 | H9: WellnessCorp | I9: INS545101 | J9: david.davis@mail.com | K9: 2021 | L9: 5 | M9: May | N9: 33 | O9: =IF(N9<=20,"0-20",IF(N9<=40,"21-40",IF(N9<=60,"41-60",IF(N9<=80,"61-80","81+")))) -> 21-40 | P9: 7.9
A10: P009 | B10: Laura Davis | C10: Male | D10: 26278 | E10: 7060324619 | F10: 321 Maple Dr | G10: 44822 | H10: PulseSecure | I10: INS136631 | J10: laura.davis@mail.com | K10: 2022 | L10: 9 | M10: Sep | N10: 40 | O10: =IF(N10<=20,"0-20",IF(N10<=40,"21-40",IF(N10<=60,"41-60",IF(N10<=80,"61-80","81+")))) -> 21-40 | P10: 9.1
A11: P010 | B11: Michael Taylor | C11: Male | D11: 37177 | E11: 7081396733 | F11: 123 Elm St | G11: 44797 | H11: WellnessCorp | I11: INS866577 | J11: michael.taylor@mail.com | K11: 2022 | L11: 8 | M11: Aug | N11: 33 | O11: =IF(N11<=20,"0-20",IF(N11<=40,"21-40",IF(N11<=60,"41-60",IF(N11<=80,"61-80","81+")))) -> 21-40 | P11: 7.9
A12: P011 | B12: Emily Jones | C12: Female | D12: 24445 | E12: 8990604070 | F12: 789 Pine Rd | G12: 44831 | H12: MedCare Plus | I12: INS172991 | J12: emily.jones@mail.com | K12: 2022 | L12: 9 | M12: Sep | N12: 36 | O12: =IF(N12<=20,"0-20",IF(N12<=40,"21-40",IF(N12<=60,"41-60",IF(N12<=80,"61-80","81+")))) -> 21-40 | P12: 9.9
A13: P012 | B13: Laura Davis | C13: Female | D13: 33580 | E13: 8135666049 | F13: 321 Maple Dr | G13: 45043 | H13: MedCare Plus | I13: INS104014 | J13: laura.davis@mail.com | K13: 2023 | L13: 4 | M13: Apr | N13: 24 | O13: =IF(N13<=20,"0-20",IF(N13<=40,"21-40",IF(N13<=60,"41-60",IF(N13<=80,"61-80","81+")))) -> 21-40 | P13: 7.1
... A51: P050 | B51: Laura Wilson | C51: Male | D51: 34330 | E51: 8301134730 | F51: 321 Maple Dr | G51: 45044 | H51: WellnessCorp | I51: INS712210 | J51: laura.wilson@mail.com | K51: 2023 | L51: 4 | M51: Apr | N51: 67 | O51: =IF(N51<=20,"0-20",IF(N51<=40,"21-40",IF(N51<=60,"41-60",IF(N51<=80,"61-80","81+")))) -> 61-80 | P51: 8.5

Sheet Treatment Data
A1: treatment_id | B1: appointment_id | C1: treatment_type | D1: description | E1: cost | F1: treatment_date
A2: T003 | B2: A003 | C2: MRI | D2: Standard procedure | E2: 3731.55 | F2: 45105
A3: T005 | B3: A005 | C3: ECG | D3: Standard procedure | E3: 582.05 | F3: 45113
A4: T006 | B4: A006 | C4: Chemotherapy | D4: Standard procedure | E4: 1381 | F4: 45096
A5: T009 | B5: A009 | C5: Physiotherapy | D5: Standard procedure | E5: 4541.14 | F5: 44990
A6: T010 | B6: A010 | C6: Physiotherapy | D6: Standard procedure | E6: 1595.67 | F6: 44939
A7: T012 | B7: A012 | C7: Chemotherapy | D7: Standard procedure | E7: 771.2 | F7: 45053
A8: T013 | B8: A013 | C8: MRI | D8: Standard procedure | E8: 4704.96 | F8: 45154
A9: T023 | B9: A023 | C9: MRI | D9: Standard procedure | E9: 3246.5 | F9: 45055
A10: T026 | B10: A026 | C10: Chemotherapy | D10: Standard procedure | E10: 2360.97 | F10: 45002
A11: T027 | B11: A027 | C11: X-Ray | D11: Standard procedure | E11: 1048.49 | F11: 45244
A12: T028 | B12: A028 | C12: Chemotherapy | D12: Standard procedure | E12: 1315.17 | F12: 45228
A13: T030 | B13: A030 | C13: Chemotherapy | D13: Standard procedure | E13: 1316.47 | F13: 45167
... A201: T200 | B201: A200 | C201: X-Ray | D201: Basic screening | E201: 3288.15 | F201: 45290

Sheet Calendar
A1: Calendar
A2: 44197
A3: 44198
A4: 44199
A5: 44200
A6: 44201
A7: 44202
A8: 44203
A9: 44204
A10: 44205
A11: 44206
A12: 44207
A13: 44208
... A1096: 45291

Sheet Appointment Data
A1: appointment_id | B1: patient_id | C1: doctor_id | D1: appointment_date | E1: appointment_time | F1: reason_for_visit | G1: status
A2: A001 | B2: P034 | C2: D009 | D2: 45147 | E2: 0.63541667 | F2: Therapy | G2: Scheduled
A3: A002 | B3: P032 | C3: D004 | D3: 45086 | E3: 0.60416667 | F3: Therapy | G3: No-show
A4: A003 | B4: P048 | C4: D004 | D4: 45105 | E4: 0.33333333 | F4: Consultation | G4: Cancelled
A5: A004 | B5: P025 | C5: D006 | D5: 45170 | E5: 0.38541667 | F5: Consultation | G5: Cancelled
A6: A005 | B6: P040 | C6: D003 | D6: 45113 | E6: 0.53125 | F6: Emergency | G6: No-show
A7: A006 | B7: P045 | C7: D006 | D7: 45096 | E7: 0.67708333 | F7: Checkup | G7: Scheduled
A8: A007 | B8: P001 | C8: D007 | D8: 45025 | E8: 0.4375 | F8: Consultation | G8: Scheduled
A9: A008 | B9: P016 | C9: D010 | D9: 45070 | E9: 0.36458333 | F9: Consultation | G9: Cancelled
A10: A009 | B10: P039 | C10: D010 | D10: 44990 | E10: 0.57291667 | F10: Follow-up | G10: Scheduled
A11: A010 | B11: P005 | C11: D003 | D11: 44939 | E11: 0.64583333 | F11: Therapy | G11: Completed
A12: A011 | B12: P022 | C12: D007 | D12: 45242 | E12: 0.66666667 | F12: Checkup | G12: No-show
A13: A012 | B13: P029 | C13: D003 | D13: 45053 | E13: 0.41666667 | F13: Follow-up | G13: Completed
... A201: A200 | B201: P007 | C201: D005 | D201: 45290 | E201: 0.42708333 | F201: Consultation | G201: Cancelled

Sheet Sheet8
A1: Count of doctor_id
A2: 10
A5: No. Of Patients
A6: 50
G8: Row Labels | H8: Count of patient name
A9: Sum of amount | G9: Female | H9: 19
A10: 551249.85 | G10: Male | H10: 31
G11: Grand Total | H11: 50
A13: Average of amount
A14: 2756.2492
A17: Patient Satisfaction level
A18: 8.26
A20: Row Labels | B20: Distinct Count of patient_id
A21: Cancelled | B21: 36
A22: Completed | B22: 33
A23: No-show | B23: 30
A24: Scheduled | B24: 30
A25: Grand Total | B25: 48
A34: Row Labels | B34: Count of patient_id
A35: Cancelled | B35: 51
A36: Completed | B36: 46
A37: No-show | B37: 52
A38: Scheduled | B38: 51
A39: Grand Total | B39: 200
A50: Row Labels | B50: Count of patient_id
A51: Failed | B51: 67
A52: Paid | B52: 64
A53: Pending | B53: 69
A54: Grand Total | B54: 200
A67: Row Labels | B67: Count of patient_id
A68: 21-40 | B68: 20
A69: 41-60 | B69: 11
A70: 61-80 | B70: 14
A71: 81+ | B71: 5
A72: Grand Total | B72: 50
L75: Row Labels | M75: Count of patient name
L76: 15-Jan | M76: 1
L77: 19-Jan | M77: 1
L78: 23-Jan | M78: 1
L79: 26-Jan | M79: 1
...

Sheet Overview

Sheet Finance

Sheet Doctor
O7: Doctor Details (Select ID)
O9: Doctor Id | Q9: doctor_id
O11: Doctor Name | Q11: =VLOOKUP($Q$9,'Doctor Data'!$A$1:$G$11,S11,FALSE) -> Doctor Name | S11: 2
O13: Specialization | Q13: =VLOOKUP($Q$9,'Doctor Data'!$A$1:$G$11,S13,FALSE) -> specialization | S13: 3
O15: Phone Number | Q15: =VLOOKUP($Q$9,'Doctor Data'!$A$1:$G$11,S15,FALSE) -> phone_number | S15: 4
O17: Years Experience | Q17: =VLOOKUP($Q$9,'Doctor Data'!$A$1:$G$11,S17,FALSE) -> years_experience | S17: 5
O19: Hospital Branch | Q19: =VLOOKUP($Q$9,'Doctor Data'!$A$1:$G$11,S19,FALSE) -> hospital_branch | S19: 6
O21: Email | Q21: =VLOOKUP($Q$9,'Doctor Data'!$A$1:$G$11,S21,FALSE) -> email | S21: 7

Sheet Patient
O7: Patient Details (Select ID)
O9: Patient Id | Q9: P004
O11: Patient Name | Q11: =VLOOKUP($Q$9,'Patient Data'!$A$1:$P$51,Patient!V11,FALSE) -> Michael Johnson | V11: 2
O13: Gender | Q13: =VLOOKUP($Q$9,'Patient Data'!$A$1:$P$51,Patient!V13,FALSE) -> Female | V13: 3
O15: Phone Number | Q15: =VLOOKUP($Q$9,'Patient Data'!$A$1:$P$51,Patient!V15,FALSE) -> 9019443432 | V15: 5
O17: Registration Date | Q17: =VLOOKUP($Q$9,'Patient Data'!$A$1:$P$51,Patient!V17,FALSE) -> 44257 | V17: 7
O19: Insurance Provider | Q19: =VLOOKUP($Q$9,'Patient Data'!$A$1:$P$51,Patient!V19,FALSE) -> HealthIndia | V19: 8
O21: Insurance Number | Q21: =VLOOKUP($Q$9,'Patient Data'!$A$1:$P$51,Patient!V21,FALSE) -> INS789944 | V21: 9
O23: Email | Q23: =VLOOKUP($Q$9,'Patient Data'!$A$1:$P$51,Patient!V23,FALSE) -> michael.johnson@mail.com | V23: 10
O25: Address | Q25: =VLOOKUP($Q$9,'Patient Data'!$A$1:$P$51,Patient!V25,FALSE) -> 123 Elm St | V25: 6

Sheet Appointment
P7: Appointment Details (Select ID)
P9: Appointment Id | R9: appointment_id
P11: Patient ID | R11: =VLOOKUP($R$9,'Appointment Data'!$A$1:$G$201,Appointment!V11,FALSE) -> patient_id | V11: 2
P13: Doctor ID | R13: =VLOOKUP($R$9,'Appointment Data'!$A$1:$G$201,Appointment!V13,FALSE) -> doctor_id | V13: 3
P15: Appointment Date | R15: =VLOOKUP($R$9,'Appointment Data'!$A$1:$G$201,Appointment!V15,FALSE) -> appointment_date | V15: 4
P17: Appointment Time | R17: =VLOOKUP($R$9,'Appointment Data'!$A$1:$G$201,Appointment!V17,FALSE) -> appointment_time | V17: 5
P19: Reason to visit | R19: =VLOOKUP($R$9,'Appointment Data'!$A$1:$G$201,Appointment!V19,FALSE) -> reason_for_visit | V19: 6
P21: Status | R21: =VLOOKUP($R$9,'Appointment Data'!$A$1:$G$201,Appointment!V21,FALSE) -> status | V21: 7
V23: 8
V25: 9
